Jul 31, Tue 21:07:40,424 - DeviceService - INFO - Init
Jul 31, Tue 21:10:08,191 - DeviceService - INFO - Init
Jul 31, Tue 21:10:30,753 - DeviceService - INFO - Init
Jul 31, Tue 21:12:13,575 - DeviceService - INFO - Init
Jul 31, Tue 21:19:13,894 - DeviceService - INFO - Init
Jul 31, Tue 21:27:44,946 - DeviceService - INFO - Init
Jul 31, Tue 21:27:55,667 - DeviceService - INFO - Init
Jul 31, Tue 21:28:07,26 - DeviceService - INFO - Init
Jul 31, Tue 21:30:43,803 - DeviceService - INFO - Init
Jul 31, Tue 21:30:49,953 - DeviceService - INFO - Init
Jul 31, Tue 21:31:37,559 - DeviceService - INFO - Init
Jul 31, Tue 21:31:58,342 - DeviceService - INFO - Init
Jul 31, Tue 21:32:06,328 - DeviceService - INFO - Init
Jul 31, Tue 21:32:41,680 - DeviceService - INFO - Init
Jul 31, Tue 21:42:24,627 - DeviceService - INFO - Init
Jul 31, Tue 21:42:48,618 - DeviceService - INFO - Init
Jul 31, Tue 21:43:29,888 - DeviceService - INFO - Init
Jul 31, Tue 21:44:53,279 - DeviceService - INFO - Init
Jul 31, Tue 21:45:04,834 - DeviceService - INFO - Init
Jul 31, Tue 21:45:07,792 - DeviceService - INFO - Init
Jul 31, Tue 21:46:50,903 - DeviceService - INFO - Init
Jul 31, Tue 21:47:40,107 - DeviceService - INFO - Init
Jul 31, Tue 21:48:51,200 - DeviceService - INFO - Init
Jul 31, Tue 21:49:39,223 - DeviceService - INFO - Init
Jul 31, Tue 21:51:51,286 - DeviceService - INFO - Init
Jul 31, Tue 21:52:34,940 - DeviceService - INFO - Init
Jul 31, Tue 21:53:34,852 - DeviceService - INFO - Init
Jul 31, Tue 21:54:05,809 - DeviceService - INFO - Init
Jul 31, Tue 21:55:26,760 - DeviceService - INFO - Init
Jul 31, Tue 21:56:17,655 - DeviceService - INFO - Init
Jul 31, Tue 21:57:42,328 - DeviceService - INFO - Init
Jul 31, Tue 21:57:44,374 - django.request - ERROR - Internal Server Error: /
Traceback (most recent call last):
  File "C:\Users\leven\Documents\GitHub\DjangoHome\venv\lib\site-packages\django\core\handlers\exception.py", line 41, in inner
    response = get_response(request)
  File "C:\Users\leven\Documents\GitHub\DjangoHome\venv\lib\site-packages\django\core\handlers\base.py", line 249, in _legacy_get_response
    response = self._get_response(request)
  File "C:\Users\leven\Documents\GitHub\DjangoHome\venv\lib\site-packages\django\core\handlers\base.py", line 187, in _get_response
    response = self.process_exception_by_middleware(e, request)
  File "C:\Users\leven\Documents\GitHub\DjangoHome\venv\lib\site-packages\django\core\handlers\base.py", line 185, in _get_response
    response = wrapped_callback(request, *callback_args, **callback_kwargs)
  File "C:\Users\leven\Documents\GitHub\DjangoHome\app\views.py", line 18, in home
    'year':datetime.now().year,
  File "C:\Users\leven\Documents\GitHub\DjangoHome\venv\lib\site-packages\django\shortcuts.py", line 30, in render
    content = loader.render_to_string(template_name, context, request, using=using)
  File "C:\Users\leven\Documents\GitHub\DjangoHome\venv\lib\site-packages\django\template\loader.py", line 68, in render_to_string
    return template.render(context, request)
  File "C:\Users\leven\Documents\GitHub\DjangoHome\venv\lib\site-packages\django\template\backends\django.py", line 66, in render
    return self.template.render(context)
  File "C:\Users\leven\Documents\GitHub\DjangoHome\venv\lib\site-packages\django\template\base.py", line 207, in render
    return self._render(context)
  File "C:\Users\leven\Documents\GitHub\DjangoHome\venv\lib\site-packages\django\template\base.py", line 199, in _render
    return self.nodelist.render(context)
  File "C:\Users\leven\Documents\GitHub\DjangoHome\venv\lib\site-packages\django\template\base.py", line 990, in render
    bit = node.render_annotated(context)
  File "C:\Users\leven\Documents\GitHub\DjangoHome\venv\lib\site-packages\django\template\base.py", line 957, in render_annotated
    return self.render(context)
  File "C:\Users\leven\Documents\GitHub\DjangoHome\venv\lib\site-packages\django\template\loader_tags.py", line 177, in render
    return compiled_parent._render(context)
  File "C:\Users\leven\Documents\GitHub\DjangoHome\venv\lib\site-packages\django\template\base.py", line 199, in _render
    return self.nodelist.render(context)
  File "C:\Users\leven\Documents\GitHub\DjangoHome\venv\lib\site-packages\django\template\base.py", line 990, in render
    bit = node.render_annotated(context)
  File "C:\Users\leven\Documents\GitHub\DjangoHome\venv\lib\site-packages\django\template\base.py", line 957, in render_annotated
    return self.render(context)
  File "C:\Users\leven\Documents\GitHub\DjangoHome\venv\lib\site-packages\django\template\defaulttags.py", line 458, in render
    url = reverse(view_name, args=args, kwargs=kwargs, current_app=current_app)
  File "C:\Users\leven\Documents\GitHub\DjangoHome\venv\lib\site-packages\django\urls\base.py", line 91, in reverse
    return force_text(iri_to_uri(resolver._reverse_with_prefix(view, prefix, *args, **kwargs)))
  File "C:\Users\leven\Documents\GitHub\DjangoHome\venv\lib\site-packages\django\urls\resolvers.py", line 497, in _reverse_with_prefix
    raise NoReverseMatch(msg)
NoReverseMatch: Reverse for 'about' not found. 'about' is not a valid view function or pattern name.
Jul 31, Tue 21:57:45,405 - django.request - WARNING - Not Found: /favicon.ico
Jul 31, Tue 21:58:35,32 - DeviceService - INFO - Init
Jul 31, Tue 22:00:41,582 - DeviceService - INFO - Init
Jul 31, Tue 22:19:26,404 - DeviceService - INFO - Init
Jul 31, Tue 22:26:35,415 - DeviceService - INFO - Init
Jul 31, Tue 23:36:05,483 - DeviceService - INFO - Init
Jul 31, Tue 23:40:49,805 - DeviceService - INFO - Init
Aug 02, Thu 21:49:22,647 - DeviceService - INFO - Init
Aug 02, Thu 22:27:07,973 - django.request - ERROR - Internal Server Error: /Devices
Traceback (most recent call last):
  File "C:\Users\leven\Documents\GitHub\DjangoHome\venv\lib\site-packages\django\core\handlers\exception.py", line 41, in inner
    response = get_response(request)
  File "C:\Users\leven\Documents\GitHub\DjangoHome\venv\lib\site-packages\django\core\handlers\base.py", line 249, in _legacy_get_response
    response = self._get_response(request)
  File "C:\Users\leven\Documents\GitHub\DjangoHome\venv\lib\site-packages\django\core\handlers\base.py", line 187, in _get_response
    response = self.process_exception_by_middleware(e, request)
  File "C:\Users\leven\Documents\GitHub\DjangoHome\venv\lib\site-packages\django\core\handlers\base.py", line 185, in _get_response
    response = wrapped_callback(request, *callback_args, **callback_kwargs)
  File "C:\Users\leven\Documents\GitHub\DjangoHome\venv\lib\site-packages\django\views\decorators\csrf.py", line 58, in wrapped_view
    return view_func(*args, **kwargs)
  File "C:\Users\leven\Documents\GitHub\DjangoHome\venv\lib\site-packages\django\views\generic\base.py", line 68, in view
    return self.dispatch(request, *args, **kwargs)
  File "C:\Users\leven\Documents\GitHub\DjangoHome\venv\lib\site-packages\rest_framework\views.py", line 483, in dispatch
    response = self.handle_exception(exc)
  File "C:\Users\leven\Documents\GitHub\DjangoHome\venv\lib\site-packages\rest_framework\views.py", line 443, in handle_exception
    self.raise_uncaught_exception(exc)
  File "C:\Users\leven\Documents\GitHub\DjangoHome\venv\lib\site-packages\rest_framework\views.py", line 480, in dispatch
    response = handler(request, *args, **kwargs)
  File "C:\Users\leven\Documents\GitHub\DjangoHome\app\Controllers\DeviceController.py", line 28, in put
    device = self.__deviceRepo.Save(request.data)
  File "C:\Users\leven\Documents\GitHub\DjangoHome\app\Repositories\DeviceRepository.py", line 34, in Save
    function = self.__functionRepo.Save(functionDict)
  File "C:\Users\leven\Documents\GitHub\DjangoHome\app\Repositories\FunctionRepository.py", line 49, in Save
    property = self.__propertyRepo.Save(propertyDict)
  File "C:\Users\leven\Documents\GitHub\DjangoHome\app\Repositories\PropertyRepository.py", line 38, in Save
    model.Name = data['Name']
KeyError: 'Name'
Aug 02, Thu 22:27:12,463 - django.request - ERROR - Internal Server Error: /Devices
Traceback (most recent call last):
  File "C:\Users\leven\Documents\GitHub\DjangoHome\venv\lib\site-packages\django\core\handlers\exception.py", line 41, in inner
    response = get_response(request)
  File "C:\Users\leven\Documents\GitHub\DjangoHome\venv\lib\site-packages\django\core\handlers\base.py", line 249, in _legacy_get_response
    response = self._get_response(request)
  File "C:\Users\leven\Documents\GitHub\DjangoHome\venv\lib\site-packages\django\core\handlers\base.py", line 187, in _get_response
    response = self.process_exception_by_middleware(e, request)
  File "C:\Users\leven\Documents\GitHub\DjangoHome\venv\lib\site-packages\django\core\handlers\base.py", line 185, in _get_response
    response = wrapped_callback(request, *callback_args, **callback_kwargs)
  File "C:\Users\leven\Documents\GitHub\DjangoHome\venv\lib\site-packages\django\views\decorators\csrf.py", line 58, in wrapped_view
    return view_func(*args, **kwargs)
  File "C:\Users\leven\Documents\GitHub\DjangoHome\venv\lib\site-packages\django\views\generic\base.py", line 68, in view
    return self.dispatch(request, *args, **kwargs)
  File "C:\Users\leven\Documents\GitHub\DjangoHome\venv\lib\site-packages\rest_framework\views.py", line 483, in dispatch
    response = self.handle_exception(exc)
  File "C:\Users\leven\Documents\GitHub\DjangoHome\venv\lib\site-packages\rest_framework\views.py", line 443, in handle_exception
    self.raise_uncaught_exception(exc)
  File "C:\Users\leven\Documents\GitHub\DjangoHome\venv\lib\site-packages\rest_framework\views.py", line 480, in dispatch
    response = handler(request, *args, **kwargs)
  File "C:\Users\leven\Documents\GitHub\DjangoHome\app\Controllers\DeviceController.py", line 28, in put
    device = self.__deviceRepo.Save(request.data)
  File "C:\Users\leven\Documents\GitHub\DjangoHome\app\Repositories\DeviceRepository.py", line 34, in Save
    function = self.__functionRepo.Save(functionDict)
  File "C:\Users\leven\Documents\GitHub\DjangoHome\app\Repositories\FunctionRepository.py", line 49, in Save
    property = self.__propertyRepo.Save(propertyDict)
  File "C:\Users\leven\Documents\GitHub\DjangoHome\app\Repositories\PropertyRepository.py", line 38, in Save
    model.Name = data['Name']
KeyError: 'Name'
